<mujoco model="ant">
  <compiler angle="degree" coordinate="local" inertiafromgeom="true" />
  <option timestep="0.03" iterations="4" />
  <custom>
    
    <numeric data="0.0 0.0 0.55 1.0 0.0 0.0 0.0 0.0 1.0 0.0 -1.0 0.0 -1.0 0.0 1.0" name="init_qpos" />
    <numeric data="1000" name="constraint_limit_stiffness" />
    <numeric data="4000" name="constraint_stiffness" />
    <numeric data="10" name="constraint_ang_damping" />
    <numeric data="20" name="constraint_vel_damping" />
    <numeric data="0.5" name="joint_scale_pos" />
    <numeric data="0.2" name="joint_scale_ang" />
    <numeric data="0.0" name="ang_damping" />
    <numeric data="1" name="spring_mass_scale" />
    <numeric data="1" name="spring_inertia_scale" />
    <numeric data="15" name="solver_maxls" />
  </custom>
  <default>
    <joint armature="1" damping="1" limited="true" />
    <geom contype="0" conaffinity="0" condim="3" density="5.0" friction="1 0.5 0.5" rgba="0.4 0.33 0.26 1.0" />
  </default>
  <asset>
    <texture builtin="gradient" height="100" rgb1="1 1 1" rgb2="0 0 0" type="skybox" width="100" />
    <texture builtin="flat" height="1278" mark="cross" markrgb="1 1 1" name="texgeom" random="0.01" rgb1="0.8 0.6 0.4" rgb2="0.8 0.6 0.4" type="cube" width="127" />
    <texture builtin="checker" height="100" name="texplane" rgb1="0 0 0" rgb2="0.8 0.8 0.8" type="2d" width="100" />
    <material name="MatPlane" reflectance="0.5" shininess="1" specular="1" texrepeat="60 60" texture="texplane" />
    <material name="geom" texture="texgeom" texuniform="true" />
  </asset>
  <worldbody>
    <light cutoff="100" diffuse="1 1 1" dir="-0 0 -1.3" directional="true" exponent="1" pos="0 0 1.3" specular=".1 .1 .1" />
    <geom conaffinity="1" condim="3" material="MatPlane" name="floor" pos="0 0 0" size="40 40 40" type="plane" rgba="0.5 0.5 0.5 1.0" />
    <body name="torso_1" pos="0.0 0.0 0.75">
      <camera name="track_1" mode="trackcom" pos="0 -3 0.3" xyaxes="1 0 0 0 0 1" />
      <geom name="torso_geom_1" pos="0 0 0" size="0.25" type="sphere" />
      <joint armature="0" damping="0" limited="false" margin="0.01" name="root_1" pos="0 0 0" type="free" />
      <body name="front_left_leg_1" pos="0 0 0">
        <geom fromto="0.0 0.0 0.0 0.2 0.2 0.0" name="aux_1_geom_1" size="0.08" type="capsule" />
        <body name="aux_1_1" pos="0.2 0.2 0">
          <joint axis="0 0 1" name="hip_1_1" pos="0.0 0.0 0.0" range="-30 30" type="hinge" />
          <geom fromto="0.0 0.0 0.0 0.2 0.2 0.0" name="left_leg_geom_1" size="0.08" type="capsule" />
          <body pos="0.2 0.2 0">
            <joint axis="-1 1 0" name="ankle_1_1" pos="0.0 0.0 0.0" range="30 70" type="hinge" />
            <geom fromto="0.0 0.0 0.0 0.4 0.4 0.0" name="left_ankle_geom_1" size="0.08" type="capsule" />
            <geom name="left_foot_geom_1" contype="1" pos="0.4 0.4 0" size="0.08" type="sphere" mass="0" />
          </body>
        </body>
      </body>
      <body name="front_right_leg_1" pos="0 0 0">
        <geom fromto="0.0 0.0 0.0 -0.2 0.2 0.0" name="aux_2_geom_1" size="0.08" type="capsule" />
        <body name="aux_2_1" pos="-0.2 0.2 0">
          <joint axis="0 0 1" name="hip_2_1" pos="0.0 0.0 0.0" range="-30 30" type="hinge" />
          <geom fromto="0.0 0.0 0.0 -0.2 0.2 0.0" name="right_leg_geom_1" size="0.08" type="capsule" />
          <body pos="-0.2 0.2 0">
            <joint axis="1 1 0" name="ankle_2_1" pos="0.0 0.0 0.0" range="-70 -30" type="hinge" />
            <geom fromto="0.0 0.0 0.0 -0.4 0.4 0.0" name="right_ankle_geom_1" size="0.08" type="capsule" />
            <geom name="right_foot_geom_1" contype="1" pos="-0.4 0.4 0" size="0.08" type="sphere" mass="0" />
          </body>
        </body>
      </body>
      <body name="back_leg_1" pos="0 0 0">
        <geom fromto="0.0 0.0 0.0 -0.2 -0.2 0.0" name="aux_3_geom_1" size="0.08" type="capsule" />
        <body name="aux_3_1" pos="-0.2 -0.2 0">
          <joint axis="0 0 1" name="hip_3_1" pos="0.0 0.0 0.0" range="-30 30" type="hinge" />
          <geom fromto="0.0 0.0 0.0 -0.2 -0.2 0.0" name="back_leg_geom_1" size="0.08" type="capsule" />
          <body pos="-0.2 -0.2 0">
            <joint axis="-1 1 0" name="ankle_3_1" pos="0.0 0.0 0.0" range="-70 -30" type="hinge" />
            <geom fromto="0.0 0.0 0.0 -0.4 -0.4 0.0" name="third_ankle_geom_1" size="0.08" type="capsule" />
            <geom name="third_foot_geom_1" contype="1" pos="-0.4 -0.4 0" size="0.08" type="sphere" mass="0" />
          </body>
        </body>
      </body>
      <body name="right_back_leg_1" pos="0 0 0">
        <geom fromto="0.0 0.0 0.0 0.2 -0.2 0.0" name="aux_4_geom_1" size="0.08" type="capsule" />
        <body name="aux_4_1" pos="0.2 -0.2 0">
          <joint axis="0 0 1" name="hip_4_1" pos="0.0 0.0 0.0" range="-30 30" type="hinge" />
          <geom fromto="0.0 0.0 0.0 0.2 -0.2 0.0" name="rightback_leg_geom_1" size="0.08" type="capsule" />
          <body pos="0.2 -0.2 0">
            <joint axis="1 1 0" name="ankle_4_1" pos="0.0 0.0 0.0" range="30 70" type="hinge" />
            <geom fromto="0.0 0.0 0.0 0.4 -0.4 0.0" name="fourth_ankle_geom_1" size="0.08" type="capsule" />
            <geom name="fourth_foot_geom_1" contype="1" pos="0.4 -0.4 0" size="0.08" type="sphere" mass="0" />
          </body>
        </body>
      </body>
    </body><body name="torso_2" pos="3.0 0.0 0.75">
      <camera name="track_2" mode="trackcom" pos="0 -3 0.3" xyaxes="1 0 0 0 0 1" />
      <geom name="torso_geom_2" pos="0 0 0" size="0.25" type="sphere" />
      <joint armature="0" damping="0" limited="false" margin="0.01" name="root_2" pos="0 0 0" type="free" />
      <body name="front_left_leg_2" pos="0 0 0">
        <geom fromto="0.0 0.0 0.0 0.2 0.2 0.0" name="aux_1_geom_2" size="0.08" type="capsule" />
        <body name="aux_1_2" pos="0.2 0.2 0">
          <joint axis="0 0 1" name="hip_1_2" pos="0.0 0.0 0.0" range="-30 30" type="hinge" />
          <geom fromto="0.0 0.0 0.0 0.2 0.2 0.0" name="left_leg_geom_2" size="0.08" type="capsule" />
          <body pos="0.2 0.2 0">
            <joint axis="-1 1 0" name="ankle_1_2" pos="0.0 0.0 0.0" range="30 70" type="hinge" />
            <geom fromto="0.0 0.0 0.0 0.4 0.4 0.0" name="left_ankle_geom_2" size="0.08" type="capsule" />
            <geom name="left_foot_geom_2" contype="1" pos="0.4 0.4 0" size="0.08" type="sphere" mass="0" />
          </body>
        </body>
      </body>
      <body name="front_right_leg_2" pos="0 0 0">
        <geom fromto="0.0 0.0 0.0 -0.2 0.2 0.0" name="aux_2_geom_2" size="0.08" type="capsule" />
        <body name="aux_2_2" pos="-0.2 0.2 0">
          <joint axis="0 0 1" name="hip_2_2" pos="0.0 0.0 0.0" range="-30 30" type="hinge" />
          <geom fromto="0.0 0.0 0.0 -0.2 0.2 0.0" name="right_leg_geom_2" size="0.08" type="capsule" />
          <body pos="-0.2 0.2 0">
            <joint axis="1 1 0" name="ankle_2_2" pos="0.0 0.0 0.0" range="-70 -30" type="hinge" />
            <geom fromto="0.0 0.0 0.0 -0.4 0.4 0.0" name="right_ankle_geom_2" size="0.08" type="capsule" />
            <geom name="right_foot_geom_2" contype="1" pos="-0.4 0.4 0" size="0.08" type="sphere" mass="0" />
          </body>
        </body>
      </body>
      <body name="back_leg_2" pos="0 0 0">
        <geom fromto="0.0 0.0 0.0 -0.2 -0.2 0.0" name="aux_3_geom_2" size="0.08" type="capsule" />
        <body name="aux_3_2" pos="-0.2 -0.2 0">
          <joint axis="0 0 1" name="hip_3_2" pos="0.0 0.0 0.0" range="-30 30" type="hinge" />
          <geom fromto="0.0 0.0 0.0 -0.2 -0.2 0.0" name="back_leg_geom_2" size="0.08" type="capsule" />
          <body pos="-0.2 -0.2 0">
            <joint axis="-1 1 0" name="ankle_3_2" pos="0.0 0.0 0.0" range="-70 -30" type="hinge" />
            <geom fromto="0.0 0.0 0.0 -0.4 -0.4 0.0" name="third_ankle_geom_2" size="0.08" type="capsule" />
            <geom name="third_foot_geom_2" contype="1" pos="-0.4 -0.4 0" size="0.08" type="sphere" mass="0" />
          </body>
        </body>
      </body>
      <body name="right_back_leg_2" pos="0 0 0">
        <geom fromto="0.0 0.0 0.0 0.2 -0.2 0.0" name="aux_4_geom_2" size="0.08" type="capsule" />
        <body name="aux_4_2" pos="0.2 -0.2 0">
          <joint axis="0 0 1" name="hip_4_2" pos="0.0 0.0 0.0" range="-30 30" type="hinge" />
          <geom fromto="0.0 0.0 0.0 0.2 -0.2 0.0" name="rightback_leg_geom_2" size="0.08" type="capsule" />
          <body pos="0.2 -0.2 0">
            <joint axis="1 1 0" name="ankle_4_2" pos="0.0 0.0 0.0" range="30 70" type="hinge" />
            <geom fromto="0.0 0.0 0.0 0.4 -0.4 0.0" name="fourth_ankle_geom_2" size="0.08" type="capsule" />
            <geom name="fourth_foot_geom_2" contype="1" pos="0.4 -0.4 0" size="0.08" type="sphere" mass="0" />
          </body>
        </body>
      </body>
    </body><body name="torso_3" pos="6.0 0.0 0.75">
      <camera name="track_3" mode="trackcom" pos="0 -3 0.3" xyaxes="1 0 0 0 0 1" />
      <geom name="torso_geom_3" pos="0 0 0" size="0.25" type="sphere" />
      <joint armature="0" damping="0" limited="false" margin="0.01" name="root_3" pos="0 0 0" type="free" />
      <body name="front_left_leg_3" pos="0 0 0">
        <geom fromto="0.0 0.0 0.0 0.2 0.2 0.0" name="aux_1_geom_3" size="0.08" type="capsule" />
        <body name="aux_1_3" pos="0.2 0.2 0">
          <joint axis="0 0 1" name="hip_1_3" pos="0.0 0.0 0.0" range="-30 30" type="hinge" />
          <geom fromto="0.0 0.0 0.0 0.2 0.2 0.0" name="left_leg_geom_3" size="0.08" type="capsule" />
          <body pos="0.2 0.2 0">
            <joint axis="-1 1 0" name="ankle_1_3" pos="0.0 0.0 0.0" range="30 70" type="hinge" />
            <geom fromto="0.0 0.0 0.0 0.4 0.4 0.0" name="left_ankle_geom_3" size="0.08" type="capsule" />
            <geom name="left_foot_geom_3" contype="1" pos="0.4 0.4 0" size="0.08" type="sphere" mass="0" />
          </body>
        </body>
      </body>
      <body name="front_right_leg_3" pos="0 0 0">
        <geom fromto="0.0 0.0 0.0 -0.2 0.2 0.0" name="aux_2_geom_3" size="0.08" type="capsule" />
        <body name="aux_2_3" pos="-0.2 0.2 0">
          <joint axis="0 0 1" name="hip_2_3" pos="0.0 0.0 0.0" range="-30 30" type="hinge" />
          <geom fromto="0.0 0.0 0.0 -0.2 0.2 0.0" name="right_leg_geom_3" size="0.08" type="capsule" />
          <body pos="-0.2 0.2 0">
            <joint axis="1 1 0" name="ankle_2_3" pos="0.0 0.0 0.0" range="-70 -30" type="hinge" />
            <geom fromto="0.0 0.0 0.0 -0.4 0.4 0.0" name="right_ankle_geom_3" size="0.08" type="capsule" />
            <geom name="right_foot_geom_3" contype="1" pos="-0.4 0.4 0" size="0.08" type="sphere" mass="0" />
          </body>
        </body>
      </body>
      <body name="back_leg_3" pos="0 0 0">
        <geom fromto="0.0 0.0 0.0 -0.2 -0.2 0.0" name="aux_3_geom_3" size="0.08" type="capsule" />
        <body name="aux_3_3" pos="-0.2 -0.2 0">
          <joint axis="0 0 1" name="hip_3_3" pos="0.0 0.0 0.0" range="-30 30" type="hinge" />
          <geom fromto="0.0 0.0 0.0 -0.2 -0.2 0.0" name="back_leg_geom_3" size="0.08" type="capsule" />
          <body pos="-0.2 -0.2 0">
            <joint axis="-1 1 0" name="ankle_3_3" pos="0.0 0.0 0.0" range="-70 -30" type="hinge" />
            <geom fromto="0.0 0.0 0.0 -0.4 -0.4 0.0" name="third_ankle_geom_3" size="0.08" type="capsule" />
            <geom name="third_foot_geom_3" contype="1" pos="-0.4 -0.4 0" size="0.08" type="sphere" mass="0" />
          </body>
        </body>
      </body>
      <body name="right_back_leg_3" pos="0 0 0">
        <geom fromto="0.0 0.0 0.0 0.2 -0.2 0.0" name="aux_4_geom_3" size="0.08" type="capsule" />
        <body name="aux_4_3" pos="0.2 -0.2 0">
          <joint axis="0 0 1" name="hip_4_3" pos="0.0 0.0 0.0" range="-30 30" type="hinge" />
          <geom fromto="0.0 0.0 0.0 0.2 -0.2 0.0" name="rightback_leg_geom_3" size="0.08" type="capsule" />
          <body pos="0.2 -0.2 0">
            <joint axis="1 1 0" name="ankle_4_3" pos="0.0 0.0 0.0" range="30 70" type="hinge" />
            <geom fromto="0.0 0.0 0.0 0.4 -0.4 0.0" name="fourth_ankle_geom_3" size="0.08" type="capsule" />
            <geom name="fourth_foot_geom_3" contype="1" pos="0.4 -0.4 0" size="0.08" type="sphere" mass="0" />
          </body>
        </body>
      </body>
    </body><body name="torso_4" pos="9.0 0.0 0.75">
      <camera name="track_4" mode="trackcom" pos="0 -3 0.3" xyaxes="1 0 0 0 0 1" />
      <geom name="torso_geom_4" pos="0 0 0" size="0.25" type="sphere" />
      <joint armature="0" damping="0" limited="false" margin="0.01" name="root_4" pos="0 0 0" type="free" />
      <body name="front_left_leg_4" pos="0 0 0">
        <geom fromto="0.0 0.0 0.0 0.2 0.2 0.0" name="aux_1_geom_4" size="0.08" type="capsule" />
        <body name="aux_1_4" pos="0.2 0.2 0">
          <joint axis="0 0 1" name="hip_1_4" pos="0.0 0.0 0.0" range="-30 30" type="hinge" />
          <geom fromto="0.0 0.0 0.0 0.2 0.2 0.0" name="left_leg_geom_4" size="0.08" type="capsule" />
          <body pos="0.2 0.2 0">
            <joint axis="-1 1 0" name="ankle_1_4" pos="0.0 0.0 0.0" range="30 70" type="hinge" />
            <geom fromto="0.0 0.0 0.0 0.4 0.4 0.0" name="left_ankle_geom_4" size="0.08" type="capsule" />
            <geom name="left_foot_geom_4" contype="1" pos="0.4 0.4 0" size="0.08" type="sphere" mass="0" />
          </body>
        </body>
      </body>
      <body name="front_right_leg_4" pos="0 0 0">
        <geom fromto="0.0 0.0 0.0 -0.2 0.2 0.0" name="aux_2_geom_4" size="0.08" type="capsule" />
        <body name="aux_2_4" pos="-0.2 0.2 0">
          <joint axis="0 0 1" name="hip_2_4" pos="0.0 0.0 0.0" range="-30 30" type="hinge" />
          <geom fromto="0.0 0.0 0.0 -0.2 0.2 0.0" name="right_leg_geom_4" size="0.08" type="capsule" />
          <body pos="-0.2 0.2 0">
            <joint axis="1 1 0" name="ankle_2_4" pos="0.0 0.0 0.0" range="-70 -30" type="hinge" />
            <geom fromto="0.0 0.0 0.0 -0.4 0.4 0.0" name="right_ankle_geom_4" size="0.08" type="capsule" />
            <geom name="right_foot_geom_4" contype="1" pos="-0.4 0.4 0" size="0.08" type="sphere" mass="0" />
          </body>
        </body>
      </body>
      <body name="back_leg_4" pos="0 0 0">
        <geom fromto="0.0 0.0 0.0 -0.2 -0.2 0.0" name="aux_3_geom_4" size="0.08" type="capsule" />
        <body name="aux_3_4" pos="-0.2 -0.2 0">
          <joint axis="0 0 1" name="hip_3_4" pos="0.0 0.0 0.0" range="-30 30" type="hinge" />
          <geom fromto="0.0 0.0 0.0 -0.2 -0.2 0.0" name="back_leg_geom_4" size="0.08" type="capsule" />
          <body pos="-0.2 -0.2 0">
            <joint axis="-1 1 0" name="ankle_3_4" pos="0.0 0.0 0.0" range="-70 -30" type="hinge" />
            <geom fromto="0.0 0.0 0.0 -0.4 -0.4 0.0" name="third_ankle_geom_4" size="0.08" type="capsule" />
            <geom name="third_foot_geom_4" contype="1" pos="-0.4 -0.4 0" size="0.08" type="sphere" mass="0" />
          </body>
        </body>
      </body>
      <body name="right_back_leg_4" pos="0 0 0">
        <geom fromto="0.0 0.0 0.0 0.2 -0.2 0.0" name="aux_4_geom_4" size="0.08" type="capsule" />
        <body name="aux_4_4" pos="0.2 -0.2 0">
          <joint axis="0 0 1" name="hip_4_4" pos="0.0 0.0 0.0" range="-30 30" type="hinge" />
          <geom fromto="0.0 0.0 0.0 0.2 -0.2 0.0" name="rightback_leg_geom_4" size="0.08" type="capsule" />
          <body pos="0.2 -0.2 0">
            <joint axis="1 1 0" name="ankle_4_4" pos="0.0 0.0 0.0" range="30 70" type="hinge" />
            <geom fromto="0.0 0.0 0.0 0.4 -0.4 0.0" name="fourth_ankle_geom_4" size="0.08" type="capsule" />
            <geom name="fourth_foot_geom_4" contype="1" pos="0.4 -0.4 0" size="0.08" type="sphere" mass="0" />
          </body>
        </body>
      </body>
    </body></worldbody>
  <actuator>
    <motor ctrllimited="true" ctrlrange="-1.0 1.0" joint="hip_4_1" gear="150" /><motor ctrllimited="true" ctrlrange="-1.0 1.0" joint="ankle_4_1" gear="150" /><motor ctrllimited="true" ctrlrange="-1.0 1.0" joint="hip_1_1" gear="150" /><motor ctrllimited="true" ctrlrange="-1.0 1.0" joint="ankle_1_1" gear="150" /><motor ctrllimited="true" ctrlrange="-1.0 1.0" joint="hip_2_1" gear="150" /><motor ctrllimited="true" ctrlrange="-1.0 1.0" joint="ankle_2_1" gear="150" /><motor ctrllimited="true" ctrlrange="-1.0 1.0" joint="hip_3_1" gear="150" /><motor ctrllimited="true" ctrlrange="-1.0 1.0" joint="ankle_3_1" gear="150" /><motor ctrllimited="true" ctrlrange="-1.0 1.0" joint="hip_4_2" gear="150" /><motor ctrllimited="true" ctrlrange="-1.0 1.0" joint="ankle_4_2" gear="150" /><motor ctrllimited="true" ctrlrange="-1.0 1.0" joint="hip_1_2" gear="150" /><motor ctrllimited="true" ctrlrange="-1.0 1.0" joint="ankle_1_2" gear="150" /><motor ctrllimited="true" ctrlrange="-1.0 1.0" joint="hip_2_2" gear="150" /><motor ctrllimited="true" ctrlrange="-1.0 1.0" joint="ankle_2_2" gear="150" /><motor ctrllimited="true" ctrlrange="-1.0 1.0" joint="hip_3_2" gear="150" /><motor ctrllimited="true" ctrlrange="-1.0 1.0" joint="ankle_3_2" gear="150" /><motor ctrllimited="true" ctrlrange="-1.0 1.0" joint="hip_4_3" gear="150" /><motor ctrllimited="true" ctrlrange="-1.0 1.0" joint="ankle_4_3" gear="150" /><motor ctrllimited="true" ctrlrange="-1.0 1.0" joint="hip_1_3" gear="150" /><motor ctrllimited="true" ctrlrange="-1.0 1.0" joint="ankle_1_3" gear="150" /><motor ctrllimited="true" ctrlrange="-1.0 1.0" joint="hip_2_3" gear="150" /><motor ctrllimited="true" ctrlrange="-1.0 1.0" joint="ankle_2_3" gear="150" /><motor ctrllimited="true" ctrlrange="-1.0 1.0" joint="hip_3_3" gear="150" /><motor ctrllimited="true" ctrlrange="-1.0 1.0" joint="ankle_3_3" gear="150" /><motor ctrllimited="true" ctrlrange="-1.0 1.0" joint="hip_4_4" gear="150" /><motor ctrllimited="true" ctrlrange="-1.0 1.0" joint="ankle_4_4" gear="150" /><motor ctrllimited="true" ctrlrange="-1.0 1.0" joint="hip_1_4" gear="150" /><motor ctrllimited="true" ctrlrange="-1.0 1.0" joint="ankle_1_4" gear="150" /><motor ctrllimited="true" ctrlrange="-1.0 1.0" joint="hip_2_4" gear="150" /><motor ctrllimited="true" ctrlrange="-1.0 1.0" joint="ankle_2_4" gear="150" /><motor ctrllimited="true" ctrlrange="-1.0 1.0" joint="hip_3_4" gear="150" /><motor ctrllimited="true" ctrlrange="-1.0 1.0" joint="ankle_3_4" gear="150" /></actuator>
</mujoco>